<?xml version="1.0"?>
<robot name="lolo_auv" xmlns:xacro="http://www.ros.org/wiki/xacro">

  <xacro:property name="visual_mesh_file" value="file://$(find lolo_stonefish_sim)/data/lolo_auv/mesh/lolo.obj"/>
  <xacro:property name="prop_mesh_file" value="file://$(find lolo_stonefish_sim)/data/lolo_auv/mesh/propeller.obj"/>
  <xacro:property name="fin_mesh_file" value="file://$(find lolo_stonefish_sim)/data/lolo_auv/mesh/fin.obj"/>
  <xacro:property name="back_fin_mesh_file" value="file://$(find lolo_stonefish_sim)/data/lolo_auv/mesh/back_fin.obj"/>

  <link name="$(arg robot_namespace)/base_link">
    <visual>
      <origin xyz="0 0 0" rpy="0 0 0"/>
      <geometry>
        <mesh filename="${visual_mesh_file}" scale="1 1 1" />
      </geometry>
    </visual>
  </link>

  <link name="$(arg robot_namespace)/dvl_link"/>
  <link name="$(arg robot_namespace)/compass_link"/>
  <!--<link name="$(arg robot_namespace)/fls_link"/>-->
  <link name="$(arg robot_namespace)/imu_link"/>
  <link name="$(arg robot_namespace)/pressure_link"/>
  <link name="$(arg robot_namespace)/gps_link"/>
  <link name="$(arg robot_namespace)/camera_link"/>

  <link name="$(arg robot_namespace)/elevator">
    <visual>
      <origin xyz="0 0 0" rpy="${0.5*pi} 0 0" />
      <!--<origin rpy="-1.5707 0.0 0.0" xyz="-2.68 0.0 0.0"/>-->
      <geometry>
        <mesh filename="${back_fin_mesh_file}" scale="1 1 1"/>
      </geometry>
    </visual>
  </link>

  <link name="$(arg robot_namespace)/rudder_stbd">
    <visual>
      <origin xyz="0 0 0" rpy="${0.5*pi} 0 0" />
      <!--<origin rpy="0.0 0.0 0.0" xyz="-2.4 -0.275 0.0"/>-->
      <geometry>
        <mesh filename="${fin_mesh_file}" scale="1 1 1"/>
      </geometry>
    </visual>
  </link>

  <link name="$(arg robot_namespace)/rudder_port">
    <visual>
      <!--<origin rpy="0.0 0.0 0.0" xyz="-2.4 0.275 0.0"/>-->
      <origin xyz="0 0 0" rpy="${0.5*pi} 0 0" />
      <geometry>
        <mesh filename="${fin_mesh_file}" scale="1 1 1"/>
      </geometry>
    </visual>
  </link>

  <!--
  <link name="$(arg robot_namespace)/fin2">
    <visual>
      <origin xyz="0 0 0" rpy="${0.5*pi} 0 0" />
      <geometry>
        <mesh filename="${fin_mesh_file}" scale="1 1 1"/>
      </geometry>
    </visual>
  </link>

  <link name="$(arg robot_namespace)/fin3">
    <visual>
      <origin xyz="0 0 0" rpy="${0.5*pi} 0 0" />
      <geometry>
        <mesh filename="${fin_mesh_file}" scale="1 1 1"/>
      </geometry>
    </visual>
  </link>
  -->

  <link name="$(arg robot_namespace)/elevon_stbd">
    <visual>
      <origin xyz="0 0 0" rpy="${0.5*pi} 0 0" />
      <!--<origin rpy="1.5707 0.0 0.0" xyz="-0.8 -0.5 0.0"/>-->
      <geometry>
        <mesh filename="${fin_mesh_file}" scale="1 1 1"/>
      </geometry>
    </visual>
  </link>

  <link name="$(arg robot_namespace)/elevon_port">
    <visual>
      <origin xyz="0 0 0" rpy="${0.5*pi} 0 0" />
      <!--<origin rpy="-1.5707 0.0 0.0" xyz="-0.8 0.5 0.0"/>-->
      <geometry>
        <mesh filename="${fin_mesh_file}" scale="1 1 1"/>
      </geometry>
    </visual>
  </link>

  <link name="$(arg robot_namespace)/thruster_port">
    <visual>
      <origin xyz="0.0 0 0" rpy="0 0 ${pi}" />
      <!--<origin rpy="0.0 0.0 3.1416" xyz="-2.85 0.275 0.0"/>-->
      <geometry>
        <mesh filename="${prop_mesh_file}" scale="1 1 1"/>
      </geometry>
    </visual>
  </link>

  <link name="$(arg robot_namespace)/thruster_stbd">
    <visual>
      <origin xyz="0.0 0 0" rpy="0 0 ${pi}" />
      <!--<origin rpy="0.0 0.0 3.1416" xyz="-2.85 -0.275 0.0"/>-->
      <geometry>
        <mesh filename="${prop_mesh_file}" scale="1 1 1"/>
      </geometry>
    </visual>
  </link>

  <!-- Mount a 3D pose sensor -->
  <link name="$(arg robot_namespace)/pose_sensor_link">
    <!--<visual>-->
      <!--<geometry>-->
        <!--<box size="0.01 0.01 0.01" />-->
      <!--</geometry>-->
    <!--</visual>-->
  </link>

  <joint name="$(arg robot_namespace)/elevator_joint" type="revolute">
    <origin xyz="-2.68 0.0 0.0" rpy="${0.5*pi} 0 0" />
    <parent link="$(arg robot_namespace)/base_link" />
    <child link="$(arg robot_namespace)/elevator" />
    <limit effort="0" lower="-${pi/4.0}" upper="${pi/4.0}" velocity="0"/>
    <axis xyz="0 0 1"/>
  </joint>

  <joint name="$(arg robot_namespace)/rudder_stbd_joint" type="revolute">
    <origin xyz="-2.4 -0.275 0.0" rpy="0 0 0" />
    <parent link="$(arg robot_namespace)/base_link" />
    <child link="$(arg robot_namespace)/rudder_stbd" />
    <limit effort="0" lower="-${pi/4.0}" upper="${pi/4.0}" velocity="0"/>
    <axis xyz="0 0 1"/>
  </joint>

  <joint name="$(arg robot_namespace)/rudder_port_joint" type="revolute">
    <origin xyz="-2.4 0.275 0.0" rpy="0 0 0" />
    <parent link="$(arg robot_namespace)/base_link" />
    <child link="$(arg robot_namespace)/rudder_port" />
    <limit effort="0" lower="-${pi/4.0}" upper="${pi/4.0}" velocity="0"/>
    <axis xyz="0 0 1"/>
  </joint>

  <!--
  <joint name="$(arg robot_namespace)/fin2_joint" type="revolute">
    <origin xyz="-2.4 -0.275 -0.034" rpy="${pi} 0 0" />
    <parent link="$(arg robot_namespace)/base_link" />
    <child link="$(arg robot_namespace)/fin2" />
    <limit effort="0" lower="-${pi/4.0}" upper="${pi/4.0}" velocity="0"/>
    <axis xyz="0 0 1"/>
  </joint>

  <joint name="$(arg robot_namespace)/fin3_joint" type="revolute">
    <origin xyz="-2.4 0.275 0.0" rpy="${pi} 0 0" />
    <parent link="$(arg robot_namespace)/base_link" />
    <child link="$(arg robot_namespace)/fin3" />
    <limit effort="0" lower="-${pi/4.0}" upper="${pi/4.0}" velocity="0"/>
    <axis xyz="0 0 1"/>
  </joint>
  -->

  <joint name="$(arg robot_namespace)/elevon_stbd_joint" type="revolute">
    <origin xyz="-0.8 -0.5 0.0" rpy="${0.5*pi} 0 0" />
    <parent link="$(arg robot_namespace)/base_link" />
    <child link="$(arg robot_namespace)/elevon_stbd" />
    <limit effort="0" lower="-${pi/4.0}" upper="${pi/4.0}" velocity="0"/>
    <axis xyz="0 0 1"/>
  </joint>

  <joint name="$(arg robot_namespace)/elevon_port_joint" type="revolute">
    <origin xyz="-0.8 0.5 0.0" rpy="${-0.5*pi} 0 0" />
    <parent link="$(arg robot_namespace)/base_link" />
    <child link="$(arg robot_namespace)/elevon_port" />
    <limit effort="0" lower="-${pi/4.0}" upper="${pi/4.0}" velocity="0"/>
    <axis xyz="0 0 1"/>
  </joint>

  <!-- Propeller -->
  <joint name="$(arg robot_namespace)/thruster_stbd_joint" type="continuous">
    <origin xyz="-2.85 -0.275 0" rpy="0 0 0" />
    <axis xyz="1 0 0"/>
    <parent link="$(arg robot_namespace)/base_link"/>
    <child link="$(arg robot_namespace)/thruster_stbd"/>
  </joint>

  <joint name="$(arg robot_namespace)/thruster_port_joint" type="continuous">
    <origin xyz="-2.85 0.275 0" rpy="0 0 0" />
    <axis xyz="1 0 0"/>
    <parent link="$(arg robot_namespace)/base_link"/>
    <child link="$(arg robot_namespace)/thruster_port"/>
  </joint>

  <joint name="$(arg robot_namespace)/pose_sensor_joint" type="revolute">
    <origin xyz="0 0 0" rpy="0 0 0" />
    <parent link="$(arg robot_namespace)/base_link"/>
    <child link="$(arg robot_namespace)/pose_sensor_link"/>
    <limit effort="0" lower="0" upper="0" velocity="0"/>
  </joint>

  <joint name="$(arg robot_namespace)/dvl_joint" type="fixed">
    <origin rpy="0.0 0.0 0.0" xyz="1.25 0.0 -0.07"/>
    <parent link="$(arg robot_namespace)/base_link"/>
    <child link="$(arg robot_namespace)/dvl_link"/>
  </joint>

  <joint name="$(arg robot_namespace)/compass_joint" type="fixed">
    <origin xyz="0 0 0" rpy="0 0 0" />
    <parent link="$(arg robot_namespace)/base_link"/>
    <child link="$(arg robot_namespace)/compass_link"/>
  </joint>

  <!--<joint name="$(arg robot_namespace)/fls_joint" type="fixed">-->
    <!--<origin xyz="0 0 0" rpy="0 0 0" />-->
    <!--<parent link="$(arg robot_namespace)/base_link"/>-->
    <!--<child link="$(arg robot_namespace)/fls_link"/>-->
  <!--</joint>-->

  <joint name="$(arg robot_namespace)/imu_joint" type="fixed">
    <origin rpy="0.0 0.0 0.0" xyz="0.9 0.0 0.0"/>
    <parent link="$(arg robot_namespace)/base_link"/>
    <child link="$(arg robot_namespace)/imu_link"/>
  </joint>

  <joint name="$(arg robot_namespace)/pressure_joint" type="fixed">
    <origin rpy="0.0 0.0 0.0" xyz="0.3 0.0 0.07"/>
    <parent link="$(arg robot_namespace)/base_link"/>
    <child link="$(arg robot_namespace)/pressure_link"/>
  </joint>

  <joint name="$(arg robot_namespace)/gps_joint" type="fixed">
    <origin rpy="0.0 0.0 0.0" xyz="1.2 0.0 0.08"/>
    <parent link="$(arg robot_namespace)/base_link"/>
    <child link="$(arg robot_namespace)/gps_link"/>
  </joint>

  <joint name="$(arg robot_namespace)/camera_joint" type="fixed">
    <origin rpy="-1.5707 0.0 1.5707" xyz="-2.5 0.0 0.33"/>
    <parent link="$(arg robot_namespace)/base_link"/>
    <child link="$(arg robot_namespace)/camera_link"/>
  </joint>

</robot>
